<?xml version="1.0"?>
<!-- DO NOT EDIT: Generated from standard_vtol.sdf.jinja -->
<sdf version='1.10'>
  <model name='fighter_vtol'>
    <pose>0 0 0 0 0 0</pose>

    <!-- Links/Components -->
    <!-- fuselage + wings (main body) -->
    <link name='base_link'>
      <pose>0 0 0 0 0 0</pose> 
      <inertial>
        <pose>0 0 0 0 0 0</pose>
        <mass>5</mass>
        <inertia>
          <ixx>0.477708333333</ixx>
          <ixy>0</ixy>
          <ixz>0</ixz>
          <iyy>0.341666666667</iyy>
          <iyz>0</iyz>
          <izz>0.811041666667</izz>
        </inertia>
      </inertial>
      <collision name='base_link_collision'>
        <pose>0 0 -0.07 0 0 0</pose>
        <geometry>
          <box>
            <size>0.55 2.144 0.05</size>
          </box>
        </geometry>
        <surface>
          <contact>
            <ode>
              <kp>100000</kp>
              <kd>1.0</kd>
              <max_vel>0.1</max_vel>
              <min_depth>0.001</min_depth>
            </ode>
          </contact>
          <friction>
            <ode />
          </friction>
        </surface>
      </collision>
      <visual name='base_link_visual'>
        <pose>0 0 0 0 0 0</pose>
        <geometry>
          <mesh>
            <scale>0.001 0.001 0.001</scale> <!-- Fusion model unit is mm, sdf unit is m-->
            <uri>model://fighter_vtol/meshes/fighter_vtol_fuselage.dae</uri>
          </mesh>
        </geometry>
        <material>
          <ambient>.175 .175 .175 1.0</ambient>
          <diffuse>.175 .175 .175 1.0</diffuse>
        </material>
      </visual>
      <gravity>1</gravity>
      <velocity_decay />
      <self_collide>0</self_collide>
      <sensor name="imu_sensor" type="imu">
        <gz_frame_id>base_link</gz_frame_id>
        <always_on>1</always_on>
        <update_rate>250</update_rate>
        <imu>
          <angular_velocity>
            <x>
              <noise type="gaussian">
                <mean>0</mean>
                <stddev>0.0003394</stddev>
                <dynamic_bias_stddev>3.8785e-05</dynamic_bias_stddev>
                <dynamic_bias_correlation_time>1000</dynamic_bias_correlation_time>
              </noise>
            </x>
            <y>
              <noise type="gaussian">
                <mean>0</mean>
                <stddev>0.0003394</stddev>
                <dynamic_bias_stddev>3.8785e-05</dynamic_bias_stddev>
                <dynamic_bias_correlation_time>1000</dynamic_bias_correlation_time>
              </noise>
            </y>
            <z>
              <noise type="gaussian">
                <mean>0</mean>
                <stddev>0.0003394</stddev>
                <dynamic_bias_stddev>3.8785e-05</dynamic_bias_stddev>
                <dynamic_bias_correlation_time>1000</dynamic_bias_correlation_time>
              </noise>
            </z>
          </angular_velocity>
          <linear_acceleration>
            <x>
              <noise type="gaussian">
                <mean>0</mean>
                <stddev>0.004</stddev>
                <dynamic_bias_stddev>0.006</dynamic_bias_stddev>
                <dynamic_bias_correlation_time>300</dynamic_bias_correlation_time>
              </noise>
            </x>
            <y>
              <noise type="gaussian">
                <mean>0</mean>
                <stddev>0.004</stddev>
                <dynamic_bias_stddev>0.006</dynamic_bias_stddev>
                <dynamic_bias_correlation_time>300</dynamic_bias_correlation_time>
              </noise>
            </y>
            <z>
              <noise type="gaussian">
                <mean>0</mean>
                <stddev>0.004</stddev>
                <dynamic_bias_stddev>0.006</dynamic_bias_stddev>
                <dynamic_bias_correlation_time>300</dynamic_bias_correlation_time>
              </noise>
            </z>
          </linear_acceleration>
        </imu>
      </sensor>
      <sensor name="air_pressure_sensor" type="air_pressure">
        <gz_frame_id>base_link</gz_frame_id>
        <always_on>1</always_on>
        <update_rate>50</update_rate>
        <air_pressure>
          <pressure>
            <noise type="gaussian">
              <mean>0</mean>
              <stddev>0.01</stddev>
            </noise>
          </pressure>
        </air_pressure>
      </sensor>
      <sensor name="magnetometer_sensor" type="magnetometer">
        <gz_frame_id>base_link</gz_frame_id>
        <always_on>1</always_on>
        <update_rate>100</update_rate>
        <magnetometer>
          <!-- TODO: update to fix units and coordinate system when we move past Harmonic -->
          <!-- See https://github.com/gazebosim/gz-sim/pull/2460 -->
          <!-- 3mgauss RMS: NOTE: noise is in tesla but sensor reports data in gauss -->
          <!-- Noise modeled after IIS2MDC -->
          <x>
            <noise type="gaussian">
              <stddev>0.0001</stddev>
            </noise>
          </x>
          <y>
            <noise type="gaussian">
              <stddev>0.0001</stddev>
            </noise>
          </y>
          <z>
            <noise type="gaussian">
              <stddev>0.0001</stddev>
            </noise>
          </z>
        </magnetometer>
      </sensor>
      <sensor name="navsat_sensor" type="navsat">
        <gz_frame_id>base_link</gz_frame_id>
        <always_on>1</always_on>
        <update_rate>30</update_rate>
      </sensor>
    </link>

    <!-- the vertical motors/rotors follows the conventions used by PX4-->
    <!-- Ref: https://docs.px4.io/main/en/airframes/airframe_reference#standard-vtol -->
    <!-- motors/rotors 1 -->
    <link name='rotor_1'>
      <pose>0.32 0.502 0.397 0 0 0</pose> <!-- put the joint point here -->
      <inertial>
        <pose>0 0 0 0 0 0</pose> <!-- use (CG in fusion - link_pose) -->
        <mass>0.005</mass>
        <inertia>
          <ixx>9.75e-07</ixx>
          <ixy>0</ixy>
          <ixz>0</ixz>
          <iyy>0.000166704</iyy>
          <iyz>0</iyz>
          <izz>0.000167604</izz>
        </inertia>
      </inertial>
      <collision name='rotor_1_collision'>
        <pose>0 0 0 0 0 0</pose>
        <geometry>
          <cylinder>
            <length>0.005</length>
            <radius>0.1</radius>
          </cylinder>
        </geometry>
        <surface>
          <contact>
            <ode />
          </contact>
          <friction>
            <ode />
          </friction>
        </surface>
      </collision>
      <visual name='rotor_1_visual'>
        <pose>0 0 0 0 0 0</pose> <!-- since the prop is from the pre-built model, its origin is its CG-->
        <geometry>
          <mesh>
            <scale>1 1 1</scale>
            <uri>model://fighter_vtol/meshes/iris_prop_ccw.dae</uri>
          </mesh>
        </geometry>
        <material>
          <ambient>0 0 1 1.0</ambient>
          <diffuse>0 0 1 1.0</diffuse>
        </material>
      </visual>
      <gravity>1</gravity>
      <velocity_decay />
      <self_collide>0</self_collide>
    </link>

    <link name='rotor_2'>
      <pose>1.216 -0.502 0.397 0 0 0</pose>
      <inertial>
        <pose>0 0 0 0 0 0</pose>
        <mass>0.005</mass>
        <inertia>
          <ixx>9.75e-07</ixx>
          <ixy>0</ixy>
          <ixz>0</ixz>
          <iyy>0.000166704</iyy>
          <iyz>0</iyz>
          <izz>0.000167604</izz>
        </inertia>
      </inertial>
      <collision name='rotor_2_collision'>
        <pose>0 0 0 0 0 0</pose>
        <geometry>
          <cylinder>
            <length>0.005</length>
            <radius>0.1</radius>
          </cylinder>
        </geometry>
        <surface>
          <contact>
            <ode />
          </contact>
          <friction>
            <ode />
          </friction>
        </surface>
      </collision>
      <visual name='rotor_2_visual'>
        <pose>0 0 0 0 0 0</pose>
        <geometry>
          <mesh>
            <scale>1 1 1</scale>
            <uri>model://fighter_vtol/meshes/iris_prop_ccw.dae</uri>
          </mesh>
        </geometry>
        <material>
          <ambient>0 0 1 1.0</ambient>
          <diffuse>0 0 1 1.0</diffuse>
        </material>
      </visual>
      <gravity>1</gravity>
      <velocity_decay />
      <self_collide>0</self_collide>
    </link>

    <link name='rotor_3'>
      <pose>0.32 -0.502 0.397 0 0 0</pose>
      <inertial>
        <pose>0 0 0 0 0 0</pose>
        <mass>0.005</mass>
        <inertia>
          <ixx>9.75e-07</ixx>
          <ixy>0</ixy>
          <ixz>0</ixz>
          <iyy>0.000166704</iyy>
          <iyz>0</iyz>
          <izz>0.000167604</izz>
        </inertia>
      </inertial>
      <collision name='rotor_3_collision'>
        <pose>0 0 0 0 0 0</pose>
        <geometry>
          <cylinder>
            <length>0.005</length>
            <radius>0.1</radius>
          </cylinder>
        </geometry>
        <surface>
          <contact>
            <ode />
          </contact>
          <friction>
            <ode />
          </friction>
        </surface>
      </collision>
      <visual name='rotor_3_visual'>
        <pose>0 0 0 0 0 0</pose>
        <geometry>
          <mesh>
            <scale>1 1 1</scale>
            <uri>model://fighter_vtol/meshes/iris_prop_ccw.dae</uri>
          </mesh>
        </geometry>
        <material>
          <ambient>0 0 1 1.0</ambient>
          <diffuse>0 0 1 1.0</diffuse>
        </material>
      </visual>
      <gravity>1</gravity>
      <velocity_decay />
      <self_collide>0</self_collide>
    </link>

    <link name='rotor_4'>
      <pose>1.216 0.502 0.397 0 0 0</pose>
      <inertial>
        <pose>0 0 0 0 0 0</pose>
        <mass>0.005</mass>
        <inertia>
          <ixx>9.75e-07</ixx>
          <ixy>0</ixy>
          <ixz>0</ixz>
          <iyy>0.000166704</iyy>
          <iyz>0</iyz>
          <izz>0.000167604</izz>
        </inertia>
      </inertial>
      <collision name='rotor_4_collision'>
        <pose>0 0 0 0 0 0</pose>
        <geometry>
          <cylinder>
            <length>0.005</length>
            <radius>0.1</radius>
          </cylinder>
        </geometry>
        <surface>
          <contact>
            <ode />
          </contact>
          <friction>
            <ode />
          </friction>
        </surface>
      </collision>
      <visual name='rotor_4_visual'>
        <pose>0 0 0 0 0 0</pose>
        <geometry>
          <mesh>
            <scale>1 1 1</scale>
            <uri>model://fighter_vtol/meshes/iris_prop_ccw.dae</uri>
          </mesh>
        </geometry>
        <material>
          <ambient>0 0 1 1.0</ambient>
          <diffuse>0 0 1 1.0</diffuse>
        </material>
      </visual>
      <gravity>1</gravity>
      <velocity_decay />
      <self_collide>0</self_collide>
    </link>

    <!-- pusher motors/rotors -->
    <link name='rotor_pusher'>
      <pose>1.8 0 0.327 0 1.57 0</pose>
      <inertial>
        <pose>0 0 0 0 0 0</pose>
        <mass>0.005</mass>
        <inertia>
          <ixx>9.75e-07</ixx>
          <ixy>0</ixy>
          <ixz>0</ixz>
          <iyy>0.000166704</iyy>
          <iyz>0</iyz>
          <izz>0.000167604</izz>
        </inertia>
      </inertial>
      <collision name='rotor_pusher_collision'>
        <pose>0.0 0 -0.04 0 0 0</pose>
        <geometry>
          <cylinder>
            <length>0.005</length>
            <radius>0.06</radius>
          </cylinder>
        </geometry>
        <surface>
          <contact>
            <ode />
          </contact>
          <friction>
            <ode />
          </friction>
        </surface>
      </collision>
      <visual name='rotor_pusher_visual'>
        <pose>0 0 0 0 0 0</pose>
        <geometry>
          <mesh>
            <scale>1 1 1</scale>
            <uri>model://fighter_vtol/meshes/iris_prop_ccw.dae</uri>
          </mesh>
        </geometry>
        <material>
          <ambient>0 0 1 1.0</ambient>
          <diffuse>0 0 1 1.0</diffuse>
        </material>
      </visual>
      <gravity>1</gravity>
      <velocity_decay />
      <self_collide>0</self_collide>
    </link>

    <!--left aileron-->
    <link name="left_aileron">
      <pose> 0.907 -0.832 0.381 0 0 0</pose>
      <inertial>
        <mass>0.00000001</mass>
        <inertia>
          <ixx>0.000001</ixx>
          <ixy>0.0</ixy>
          <iyy>0.000001</iyy>
          <ixz>0.0</ixz>
          <iyz>0.0</iyz>
          <izz>0.000001</izz>
        </inertia>
        <pose>0 0.3 0 0.00 0 0.0</pose>
      </inertial>
      <visual name='left_aileron_visual'>
        <pose> -0.907 0.832 -0.381 0 0 0</pose>
        <geometry>
          <mesh>
            <scale>0.001 0.001 0.001</scale>
            <uri>model://fighter_vtol/meshes/fighter_vtol_left_aileron.dae</uri>
          </mesh>
        </geometry>
        <material>
          <ambient>0 0 1 1.0</ambient>
          <diffuse>0 0 1 1.0</diffuse>
        </material>
      </visual>
    </link>

    <!-- right aileron-->
    <link name="right_aileron">
      <pose> 0.907 0.832 0.381 0 0 0</pose>
      <inertial>
        <mass>0.00000001</mass>
        <inertia>
          <ixx>0.000001</ixx>
          <ixy>0.0</ixy>
          <iyy>0.000001</iyy>
          <ixz>0.0</ixz>
          <iyz>0.0</iyz>
          <izz>0.000001</izz>
        </inertia>
        <pose>0 -0.6 0 0.00 0 0.0</pose>
      </inertial>
      <visual name='right_aileron_visual'>
        <pose> -0.907 -0.832 -0.381 0 0 0</pose>
        <geometry>
          <mesh>
            <scale>0.001 0.001 0.001</scale>
            <uri>model://fighter_vtol/meshes/fighter_vtol_right_aileron.dae</uri>
          </mesh>
        </geometry>
        <material>
          <ambient>0 0 1 1.0</ambient>
          <diffuse>0 0 1 1.0</diffuse>
        </material>
      </visual>
    </link>

      <!-- left elevator-->
    <link name="left_elevator">
      <pose> 1.683 -0.062 0.329 0 0 0</pose>
      <inertial>
        <mass>0.00000001</mass>
        <inertia>
          <ixx>0.000001</ixx>
          <ixy>0.0</ixy>
          <iyy>0.000001</iyy>
          <ixz>0.0</ixz>
          <iyz>0.0</iyz>
          <izz>0.000001</izz>
        </inertia>
        <pose>0 -0.6 0 0.00 0 0.0</pose>
      </inertial>
      <visual name='left_elevator_visual'>
        <pose> -1.683 0.062 -0.329 0 0 0</pose>
        <geometry>
          <mesh>
            <scale>0.001 0.001 0.001</scale>
            <uri>model://fighter_vtol/meshes/fighter_vtol_left_elevator.dae</uri>
          </mesh>
        </geometry>
        <material>
          <ambient>0 0 1 1.0</ambient>
          <diffuse>0 0 1 1.0</diffuse>
        </material>
      </visual>
    </link>

    <!-- right elevator-->
    <link name="right_elevator">
      <pose> 1.683 0.062 0.329 0 0 0</pose>
      <inertial>
        <mass>0.00000001</mass>
        <inertia>
          <ixx>0.000001</ixx>
          <ixy>0.0</ixy>
          <iyy>0.000001</iyy>
          <ixz>0.0</ixz>
          <iyz>0.0</iyz>
          <izz>0.000001</izz>
        </inertia>
        <pose>0 -0.6 0 0.00 0 0.0</pose>
      </inertial>
      <visual name='right_elevator_visual'>
        <pose> -1.683 -0.062 -0.329 0 0 0</pose>
        <geometry>
          <mesh>
            <scale>0.001 0.001 0.001</scale>
            <uri>model://fighter_vtol/meshes/fighter_vtol_right_elevator.dae</uri>
          </mesh>
        </geometry>
        <material>
          <ambient>0 0 1 1.0</ambient>
          <diffuse>0 0 1 1.0</diffuse>
        </material>
      </visual>
    </link>

    <!-- rudder -->
    <link name="rudder">
      <pose> 1.636 0 0.378 0 0 0</pose>
      <inertial>
        <mass>0.00000001</mass>
        <inertia>
          <ixx>0.000001</ixx>
          <ixy>0.0</ixy>
          <iyy>0.000001</iyy>
          <ixz>0.0</ixz>
          <iyz>0.0</iyz>
          <izz>0.000001</izz>
        </inertia>
        <pose>0 0 0 0 0 0</pose>
      </inertial>
      <visual name='rudder_visual'>
        <pose> -1.636 0 -0.378 0 0 0</pose>
        <geometry>
          <mesh>
            <scale>0.001 0.001 0.001</scale>
            <uri>model://fighter_vtol/meshes/fighter_vtol_rudder.dae</uri>
          </mesh>
        </geometry>
        <material>
          <ambient>0 0 1 1</ambient>
          <diffuse>0 0 1 1</diffuse>
        </material>
      </visual>
    </link>

    <!-- Joints -->

    <!-- pusher-fuselage joint-->
    <joint name='rotor_pusher_joint' type='revolute'>
      <pose>0 0 0 0 0 0</pose>
      <child>rotor_pusher</child>
      <parent>base_link</parent>
      <axis>
        <xyz>0 0 1</xyz>
        <limit>
          <lower>-1e+16</lower>
          <upper>1e+16</upper>
        </limit>
        <dynamics>
          <spring_reference>0</spring_reference>
          <spring_stiffness>0</spring_stiffness>
        </dynamics>
      </axis>
    </joint>

    <!-- rotor_1-fuselage joint -->
    <joint name='rotor_1_joint' type='revolute'>
      <pose>0 0 0 0 0 0</pose>
      <child>rotor_1</child>
      <parent>base_link</parent>
      <axis>
        <xyz>0 0 1</xyz>
        <limit>
          <lower>-1e+16</lower>
          <upper>1e+16</upper>
        </limit>
        <dynamics>
          <spring_reference>0</spring_reference>
          <spring_stiffness>0</spring_stiffness>
        </dynamics>
      </axis>
    </joint>

    <!-- rotor_2-fuselage joint -->
    <joint name='rotor_2_joint' type='revolute'>
      <pose>0 0 0 0 0 0</pose>
      <child>rotor_2</child>
      <parent>base_link</parent>
      <axis>
        <xyz>0 0 1</xyz>
        <limit>
          <lower>-1e+16</lower>
          <upper>1e+16</upper>
        </limit>
        <dynamics>
          <spring_reference>0</spring_reference>
          <spring_stiffness>0</spring_stiffness>
        </dynamics>
      </axis>
    </joint>

    <!-- rotor_3-fuselage joint -->
    <joint name='rotor_3_joint' type='revolute'>
      <pose>0 0 0 0 0 0</pose>
      <child>rotor_3</child>
      <parent>base_link</parent>
      <axis>
        <xyz>0 0 1</xyz>
        <limit>
          <lower>-1e+16</lower>
          <upper>1e+16</upper>
        </limit>
        <dynamics>
          <spring_reference>0</spring_reference>
          <spring_stiffness>0</spring_stiffness>
        </dynamics>
      </axis>
    </joint>

    <!-- rotor_4-fuselage joint -->
    <joint name='rotor_4_joint' type='revolute'>
      <pose>0 0 0 0 0 0</pose>
      <child>rotor_4</child>
      <parent>base_link</parent>
      <axis>
        <xyz>0 0 1</xyz>
        <limit>
          <lower>-1e+16</lower>
          <upper>1e+16</upper>
        </limit>
        <dynamics>
          <spring_reference>0</spring_reference>
          <spring_stiffness>0</spring_stiffness>
        </dynamics>
      </axis>
    </joint>


    <joint name='left_aileron_joint' type='revolute'>
      <pose>0 0 0 0 0 0</pose>
      <parent>base_link</parent>
      <child>left_aileron</child>
      <axis>
        <xyz>0 1 0</xyz>
        <limit>
          <lower>-0.78</lower>
          <upper>0.78</upper>
        </limit>
        <dynamics>
          <damping>1.000</damping>
        </dynamics>
      </axis>
      <physics>
        <ode>
          <implicit_spring_damper>1</implicit_spring_damper>
        </ode>
      </physics>
    </joint>

    <joint name='right_aileron_joint' type='revolute'>
      <pose>0 0 0 0 0 0</pose>
      <parent>base_link</parent>
      <child>right_aileron</child>
      <axis>
        <xyz>0 1 0</xyz>
        <limit>
          <lower>-0.78</lower>
          <upper>0.78</upper>
        </limit>
        <dynamics>
          <damping>1.000</damping>
        </dynamics>
      </axis>
      <physics>
        <ode>
          <implicit_spring_damper>1</implicit_spring_damper>
        </ode>
      </physics>
    </joint>


    <joint name='left_elevator_joint' type='revolute'>
      <pose> 0 0 0 0 0 0</pose>
      <parent>base_link</parent>
      <child>left_elevator</child>
      <axis>
        <xyz>0 1 0</xyz>
        <limit>
          <lower>-0.78</lower>
          <upper>0.78</upper>
        </limit>
        <dynamics>
          <damping>1.000</damping>
        </dynamics>
      </axis>
      <physics>
        <ode>
          <implicit_spring_damper>1</implicit_spring_damper>
        </ode>
      </physics>
    </joint>


    <joint name='right_elevator_joint' type='revolute'>
      <parent>base_link</parent>
      <child>right_elevator</child>
      <pose> 0 0 0 0 0 0</pose>
      <axis>
        <xyz>0 1 0</xyz>
        <limit>
          <lower>-0.78</lower>
          <upper>0.78</upper>
        </limit>
        <dynamics>
          <damping>1.000</damping>
        </dynamics>
      </axis>
      <physics>
        <ode>
          <implicit_spring_damper>1</implicit_spring_damper>
        </ode>
      </physics>
    </joint>


    <joint name='rudder_joint' type='revolute'>
      <pose> 0 0 0 0 0 0</pose>
      <parent>base_link</parent>
      <child>rudder</child>
      <axis>
        <xyz>0 0 1</xyz>
        <limit>
          <lower>-0.78</lower>
          <upper>0.78</upper>
        </limit>
        <dynamics>
          <damping>1.000</damping>
        </dynamics>
      </axis>
      <physics>
        <ode>
          <implicit_spring_damper>1</implicit_spring_damper>
        </ode>
      </physics>
    </joint>

    <!-- Joints end -->

    <!-- Dynamical model Plugins -->
    <!-- left aileron -->
    <plugin filename="gz-sim-lift-drag-system" name="gz::sim::systems::LiftDrag">
      <a0>0.05984281113</a0>
      <cla>4.752798721</cla>
      <cda>0.6417112299</cda>
      <cma>0.0</cma>
      <alpha_stall>0.3391428111</alpha_stall>
      <cla_stall>-3.85</cla_stall>
      <cda_stall>-0.9233984055</cda_stall>
      <cma_stall>0</cma_stall>
      <cp>-0.05 0.3 0.05</cp>
      <area>0.50</area>
      <air_density>1.2041</air_density>
      <forward>1 0 0</forward>
      <upward>0 0 1</upward>
      <link_name>base_link</link_name>
      <control_joint_name>left_aileron_joint</control_joint_name>
      <control_joint_rad_to_cl>-1.0</control_joint_rad_to_cl>
    </plugin>
    <plugin
      filename="gz-sim-joint-position-controller-system"
      name="gz::sim::systems::JointPositionController">
      <joint_name>left_aileron_joint</joint_name>
      <sub_topic>servo_0</sub_topic> <!-- this is the default topic px4 publish-->
    </plugin>

    <!-- right aileron -->
    <plugin filename="gz-sim-lift-drag-system" name="gz::sim::systems::LiftDrag">
      <a0>0.05984281113</a0>
      <cla>4.752798721</cla>
      <cda>0.6417112299</cda>
      <cma>0.0</cma>
      <alpha_stall>0.3391428111</alpha_stall>
      <cla_stall>-3.85</cla_stall>
      <cda_stall>-0.9233984055</cda_stall>
      <cma_stall>0</cma_stall>
      <cp>-0.05 -0.3 0.05</cp>
      <area>0.50</area>
      <air_density>1.2041</air_density>
      <forward>1 0 0</forward>
      <upward>0 0 1</upward>
      <link_name>base_link</link_name>
      <control_joint_name>right_aileron_joint</control_joint_name>
      <control_joint_rad_to_cl>-1.0</control_joint_rad_to_cl>
    </plugin>
    <plugin
      filename="gz-sim-joint-position-controller-system"
      name="gz::sim::systems::JointPositionController">
      <joint_name>right_aileron_joint</joint_name>
      <sub_topic>servo_1</sub_topic>
    </plugin>


    <!-- left elevator -->
    <plugin filename="gz-sim-lift-drag-system" name="gz::sim::systems::LiftDrag">
      <a0>-0.2</a0>
      <cla>4.752798721</cla>
      <cda>0.6417112299</cda>
      <cma>0.0</cma>
      <alpha_stall>0.3391428111</alpha_stall>
      <cla_stall>-3.85</cla_stall>
      <cda_stall>-0.9233984055</cda_stall>
      <cma_stall>0</cma_stall>
      <cp>-0.5 0 0</cp>
      <area>0.01</area>
      <air_density>1.2041</air_density>
      <forward>1 0 0</forward>
      <upward>0 0 1</upward>
      <link_name>base_link</link_name>
      <control_joint_name>left_elevator_joint</control_joint_name>
      <control_joint_rad_to_cl>-12.0</control_joint_rad_to_cl>
    </plugin>
    <plugin
      filename="gz-sim-joint-position-controller-system"
      name="gz::sim::systems::JointPositionController">
      <joint_name>left_elevator_joint</joint_name>
      <sub_topic>servo_2</sub_topic>
    </plugin>

    <!-- right elevator -->
        <plugin filename="gz-sim-lift-drag-system" name="gz::sim::systems::LiftDrag">
      <a0>-0.2</a0>
      <cla>4.752798721</cla>
      <cda>0.6417112299</cda>
      <cma>0.0</cma>
      <alpha_stall>0.3391428111</alpha_stall>
      <cla_stall>-3.85</cla_stall>
      <cda_stall>-0.9233984055</cda_stall>
      <cma_stall>0</cma_stall>
      <cp>-0.5 0 0</cp>
      <area>0.01</area>
      <air_density>1.2041</air_density>
      <forward>1 0 0</forward>
      <upward>0 0 1</upward>
      <link_name>base_link</link_name>
      <control_joint_name>right_elevator_joint</control_joint_name>
      <control_joint_rad_to_cl>-12.0</control_joint_rad_to_cl>
    </plugin>
    <plugin
      filename="gz-sim-joint-position-controller-system"
      name="gz::sim::systems::JointPositionController">
      <joint_name>right_elevator_joint</joint_name>
      <sub_topic>servo_3</sub_topic>
    </plugin>

    <!-- rudder -->
    <plugin filename="gz-sim-lift-drag-system" name="gz::sim::systems::LiftDrag">
      <a0>-0.2</a0>
      <cla>4.752798721</cla>
      <cda>0.6417112299</cda>
      <cma>0.0</cma>
      <alpha_stall>0.3391428111</alpha_stall>
      <cla_stall>-3.85</cla_stall>
      <cda_stall>-0.9233984055</cda_stall>
      <cma_stall>0</cma_stall>
      <cp>-0.5 0 0</cp>
      <area>0.01</area>
      <air_density>1.2041</air_density>
      <forward>1 0 0</forward>
      <upward>0 0 1</upward>
      <link_name>base_link</link_name>
      <control_joint_name>rudder_joint</control_joint_name>
      <control_joint_rad_to_cl>-12.0</control_joint_rad_to_cl>
    </plugin>
    <plugin
      filename="gz-sim-joint-position-controller-system"
      name="gz::sim::systems::JointPositionController">
      <joint_name>rudder_joint</joint_name>
      <sub_topic>servo_4</sub_topic>
    </plugin>

    <!-- rotor 1 -->
    <plugin filename="gz-sim-multicopter-motor-model-system"
      name="gz::sim::systems::MulticopterMotorModel">
      <jointName>rotor_1_joint</jointName>
      <linkName>rotor_1</linkName>
      <turningDirection>ccw</turningDirection>
      <timeConstantUp>0.0125</timeConstantUp>
      <timeConstantDown>0.025</timeConstantDown>
      <maxRotVelocity>1500</maxRotVelocity>
      <motorConstant>2e-05</motorConstant>
      <momentConstant>0.06</momentConstant>
      <commandSubTopic>command/motor_speed</commandSubTopic>
      <motorNumber>0</motorNumber>
      <rotorDragCoefficient>0.000106428</rotorDragCoefficient>
      <rollingMomentCoefficient>1e-06</rollingMomentCoefficient>
      <rotorVelocitySlowdownSim>20</rotorVelocitySlowdownSim>
      <motorType>velocity</motorType>
    </plugin>

    <!-- rotor 2 -->
    <plugin
      filename="gz-sim-multicopter-motor-model-system"
      name="gz::sim::systems::MulticopterMotorModel">
      <jointName>rotor_2_joint</jointName>
      <linkName>rotor_2</linkName>
      <turningDirection>ccw</turningDirection>
      <timeConstantUp>0.0125</timeConstantUp>
      <timeConstantDown>0.025</timeConstantDown>
      <maxRotVelocity>1500</maxRotVelocity>
      <motorConstant>2e-05</motorConstant>
      <momentConstant>0.06</momentConstant>
      <commandSubTopic>command/motor_speed</commandSubTopic>
      <motorNumber>1</motorNumber> <!-- PX4 start with 0 -->
      <rotorDragCoefficient>0.000106428</rotorDragCoefficient>
      <rollingMomentCoefficient>1e-06</rollingMomentCoefficient>
      <rotorVelocitySlowdownSim>20</rotorVelocitySlowdownSim>
      <motorType>velocity</motorType>
    </plugin>

    <!-- rotor 3 -->
    <plugin
      filename="gz-sim-multicopter-motor-model-system"
      name="gz::sim::systems::MulticopterMotorModel">
      <jointName>rotor_3_joint</jointName>
      <linkName>rotor_3</linkName>
      <turningDirection>cw</turningDirection>
      <timeConstantUp>0.0125</timeConstantUp>
      <timeConstantDown>0.025</timeConstantDown>
      <maxRotVelocity>1500</maxRotVelocity>
      <motorConstant>2e-05</motorConstant>
      <momentConstant>0.06</momentConstant>
      <commandSubTopic>command/motor_speed</commandSubTopic>
      <motorNumber>2</motorNumber>
      <rotorDragCoefficient>0.000106428</rotorDragCoefficient>
      <rollingMomentCoefficient>1e-06</rollingMomentCoefficient>
      <rotorVelocitySlowdownSim>20</rotorVelocitySlowdownSim>
      <motorType>velocity</motorType>
    </plugin>

    <!-- rotor 4 -->
    <plugin filename="gz-sim-multicopter-motor-model-system"
      name="gz::sim::systems::MulticopterMotorModel">
      <jointName>rotor_4_joint</jointName>
      <linkName>rotor_4</linkName>
      <turningDirection>cw</turningDirection>
      <timeConstantUp>0.0125</timeConstantUp>
      <timeConstantDown>0.025</timeConstantDown>
      <maxRotVelocity>1500</maxRotVelocity>
      <motorConstant>2e-05</motorConstant>
      <momentConstant>0.06</momentConstant>
      <commandSubTopic>command/motor_speed</commandSubTopic>
      <motorNumber>3</motorNumber>
      <rotorDragCoefficient>0.000106428</rotorDragCoefficient>
      <rollingMomentCoefficient>1e-06</rollingMomentCoefficient>
      <rotorVelocitySlowdownSim>20</rotorVelocitySlowdownSim>
      <motorType>velocity</motorType>
    </plugin>

    <!-- pusher rotor -->
    <plugin
      filename="gz-sim-multicopter-motor-model-system"
      name="gz::sim::systems::MulticopterMotorModel">
      <jointName>rotor_pusher_joint</jointName>
      <linkName>rotor_pusher</linkName>
      <turningDirection>cw</turningDirection>
      <timeConstantUp>0.0125</timeConstantUp>
      <timeConstantDown>0.025</timeConstantDown>
      <maxRotVelocity>3500</maxRotVelocity>
      <motorConstant>8.54858e-06</motorConstant>
      <momentConstant>0.01</momentConstant>
      <commandSubTopic>command/motor_speed</commandSubTopic>
      <motorNumber>4</motorNumber>
      <rotorDragCoefficient>0.000106428</rotorDragCoefficient>
      <rollingMomentCoefficient>1e-06</rollingMomentCoefficient>
      <rotorVelocitySlowdownSim>20</rotorVelocitySlowdownSim>
      <motorType>velocity</motorType>
    </plugin>
    <static>0</static>
  </model>
</sdf>
